Exception in thread Thread-1:
Traceback (most recent call last):
  File "/usr/lib/python3.10/threading.py", line 1016, in _bootstrap_inner
    self.run()
  File "/home/tiendang/projects/frappe-bench/env/lib/python3.10/site-packages/redis/client.py", line 1151, in run
    pubsub.get_message(ignore_subscribe_messages=True, timeout=sleep_time)
  File "/home/tiendang/projects/frappe-bench/env/lib/python3.10/site-packages/redis/client.py", line 1013, in get_message
    response = self.parse_response(block=(timeout is None), timeout=timeout)
  File "/home/tiendang/projects/frappe-bench/env/lib/python3.10/site-packages/redis/client.py", line 824, in parse_response
    response = self._execute(conn, try_read)
  File "/home/tiendang/projects/frappe-bench/env/lib/python3.10/site-packages/redis/client.py", line 800, in _execute
    return conn.retry.call_with_retry(
  File "/home/tiendang/projects/frappe-bench/env/lib/python3.10/site-packages/redis/retry.py", line 49, in call_with_retry
    fail(error)
  File "/home/tiendang/projects/frappe-bench/env/lib/python3.10/site-packages/redis/client.py", line 802, in <lambda>
    lambda error: self._disconnect_raise_connect(conn, error),
  File "/home/tiendang/projects/frappe-bench/env/lib/python3.10/site-packages/redis/client.py", line 789, in _disconnect_raise_connect
    raise error
  File "/home/tiendang/projects/frappe-bench/env/lib/python3.10/site-packages/redis/retry.py", line 46, in call_with_retry
    return do()
  File "/home/tiendang/projects/frappe-bench/env/lib/python3.10/site-packages/redis/client.py", line 801, in <lambda>
    lambda: command(*args, **kwargs),
  File "/home/tiendang/projects/frappe-bench/env/lib/python3.10/site-packages/redis/client.py", line 818, in try_read
    if not conn.can_read(timeout=timeout):
  File "/home/tiendang/projects/frappe-bench/env/lib/python3.10/site-packages/redis/connection.py", line 478, in can_read
    return self._parser.can_read(timeout)
  File "/home/tiendang/projects/frappe-bench/env/lib/python3.10/site-packages/redis/_parsers/hiredis.py", line 75, in can_read
    return self.read_from_socket(timeout=timeout, raise_on_timeout=False)
  File "/home/tiendang/projects/frappe-bench/env/lib/python3.10/site-packages/redis/_parsers/hiredis.py", line 86, in read_from_socket
    raise ConnectionError(SERVER_CLOSED_CONNECTION_ERROR)
redis.exceptions.ConnectionError: Connection closed by server.
Traceback (most recent call last):
  File "/home/tiendang/projects/frappe-bench/env/lib/python3.10/site-packages/redis/connection.py", line 264, in connect
    sock = self.retry.call_with_retry(
  File "/home/tiendang/projects/frappe-bench/env/lib/python3.10/site-packages/redis/retry.py", line 46, in call_with_retry
    return do()
  File "/home/tiendang/projects/frappe-bench/env/lib/python3.10/site-packages/redis/connection.py", line 265, in <lambda>
    lambda: self._connect(), lambda error: self.disconnect(error)
  File "/home/tiendang/projects/frappe-bench/env/lib/python3.10/site-packages/redis/connection.py", line 627, in _connect
    raise err
  File "/home/tiendang/projects/frappe-bench/env/lib/python3.10/site-packages/redis/connection.py", line 615, in _connect
    sock.connect(socket_address)
ConnectionRefusedError: [Errno 111] Connection refused

During handling of the above exception, another exception occurred:

Traceback (most recent call last):
  File "/usr/lib/python3.10/runpy.py", line 196, in _run_module_as_main
    return _run_code(code, main_globals, None,
  File "/usr/lib/python3.10/runpy.py", line 86, in _run_code
    exec(code, run_globals)
  File "/home/tiendang/projects/frappe-bench/apps/frappe/frappe/utils/bench_helper.py", line 114, in <module>
    main()
  File "/home/tiendang/projects/frappe-bench/apps/frappe/frappe/utils/bench_helper.py", line 20, in main
    click.Group(commands=commands)(prog_name="bench")
  File "/home/tiendang/projects/frappe-bench/env/lib/python3.10/site-packages/click/core.py", line 1157, in __call__
    return self.main(*args, **kwargs)
  File "/home/tiendang/projects/frappe-bench/env/lib/python3.10/site-packages/click/core.py", line 1078, in main
    rv = self.invoke(ctx)
  File "/home/tiendang/projects/frappe-bench/env/lib/python3.10/site-packages/click/core.py", line 1688, in invoke
    return _process_result(sub_ctx.command.invoke(sub_ctx))
  File "/home/tiendang/projects/frappe-bench/env/lib/python3.10/site-packages/click/core.py", line 1688, in invoke
    return _process_result(sub_ctx.command.invoke(sub_ctx))
  File "/home/tiendang/projects/frappe-bench/env/lib/python3.10/site-packages/click/core.py", line 1434, in invoke
    return ctx.invoke(self.callback, **ctx.params)
  File "/home/tiendang/projects/frappe-bench/env/lib/python3.10/site-packages/click/core.py", line 783, in invoke
    return __callback(*args, **kwargs)
  File "/home/tiendang/projects/frappe-bench/apps/frappe/frappe/commands/scheduler.py", line 208, in start_worker
    start_worker(
  File "/home/tiendang/projects/frappe-bench/apps/frappe/frappe/utils/background_jobs.py", line 339, in start_worker
    worker.work(
  File "/home/tiendang/projects/frappe-bench/env/lib/python3.10/site-packages/rq/worker.py", line 456, in work
    self.teardown()
  File "/home/tiendang/projects/frappe-bench/env/lib/python3.10/site-packages/rq/worker.py", line 1047, in teardown
    self.unsubscribe()
  File "/home/tiendang/projects/frappe-bench/env/lib/python3.10/site-packages/rq/worker.py", line 624, in unsubscribe
    self.pubsub.unsubscribe()
  File "/home/tiendang/projects/frappe-bench/env/lib/python3.10/site-packages/redis/client.py", line 941, in unsubscribe
    return self.execute_command("UNSUBSCRIBE", *args)
  File "/home/tiendang/projects/frappe-bench/env/lib/python3.10/site-packages/redis/client.py", line 761, in execute_command
    self._execute(connection, connection.send_command, *args, **kwargs)
  File "/home/tiendang/projects/frappe-bench/env/lib/python3.10/site-packages/redis/client.py", line 800, in _execute
    return conn.retry.call_with_retry(
  File "/home/tiendang/projects/frappe-bench/env/lib/python3.10/site-packages/redis/retry.py", line 49, in call_with_retry
    fail(error)
  File "/home/tiendang/projects/frappe-bench/env/lib/python3.10/site-packages/redis/client.py", line 802, in <lambda>
    lambda error: self._disconnect_raise_connect(conn, error),
  File "/home/tiendang/projects/frappe-bench/env/lib/python3.10/site-packages/redis/client.py", line 789, in _disconnect_raise_connect
    raise error
  File "/home/tiendang/projects/frappe-bench/env/lib/python3.10/site-packages/redis/retry.py", line 46, in call_with_retry
    return do()
  File "/home/tiendang/projects/frappe-bench/env/lib/python3.10/site-packages/redis/client.py", line 801, in <lambda>
    lambda: command(*args, **kwargs),
  File "/home/tiendang/projects/frappe-bench/env/lib/python3.10/site-packages/redis/connection.py", line 464, in send_command
    self.send_packed_command(
  File "/home/tiendang/projects/frappe-bench/env/lib/python3.10/site-packages/redis/connection.py", line 434, in send_packed_command
    self.connect()
  File "/home/tiendang/projects/frappe-bench/env/lib/python3.10/site-packages/redis/connection.py", line 270, in connect
    raise ConnectionError(self._error_message(e))
redis.exceptions.ConnectionError: Error 111 connecting to 127.0.0.1:11000. Connection refused.
Exception in thread Thread-1:
Traceback (most recent call last):
  File "/usr/lib/python3.10/threading.py", line 1016, in _bootstrap_inner
    self.run()
  File "/home/tiendang/projects/frappe-bench/env/lib/python3.10/site-packages/redis/client.py", line 1151, in run
    pubsub.get_message(ignore_subscribe_messages=True, timeout=sleep_time)
  File "/home/tiendang/projects/frappe-bench/env/lib/python3.10/site-packages/redis/client.py", line 1013, in get_message
    response = self.parse_response(block=(timeout is None), timeout=timeout)
  File "/home/tiendang/projects/frappe-bench/env/lib/python3.10/site-packages/redis/client.py", line 824, in parse_response
    response = self._execute(conn, try_read)
  File "/home/tiendang/projects/frappe-bench/env/lib/python3.10/site-packages/redis/client.py", line 800, in _execute
    return conn.retry.call_with_retry(
  File "/home/tiendang/projects/frappe-bench/env/lib/python3.10/site-packages/redis/retry.py", line 49, in call_with_retry
    fail(error)
  File "/home/tiendang/projects/frappe-bench/env/lib/python3.10/site-packages/redis/client.py", line 802, in <lambda>
    lambda error: self._disconnect_raise_connect(conn, error),
  File "/home/tiendang/projects/frappe-bench/env/lib/python3.10/site-packages/redis/client.py", line 789, in _disconnect_raise_connect
    raise error
  File "/home/tiendang/projects/frappe-bench/env/lib/python3.10/site-packages/redis/retry.py", line 46, in call_with_retry
    return do()
  File "/home/tiendang/projects/frappe-bench/env/lib/python3.10/site-packages/redis/client.py", line 801, in <lambda>
    lambda: command(*args, **kwargs),
  File "/home/tiendang/projects/frappe-bench/env/lib/python3.10/site-packages/redis/client.py", line 818, in try_read
    if not conn.can_read(timeout=timeout):
  File "/home/tiendang/projects/frappe-bench/env/lib/python3.10/site-packages/redis/connection.py", line 478, in can_read
    return self._parser.can_read(timeout)
  File "/home/tiendang/projects/frappe-bench/env/lib/python3.10/site-packages/redis/_parsers/hiredis.py", line 75, in can_read
    return self.read_from_socket(timeout=timeout, raise_on_timeout=False)
  File "/home/tiendang/projects/frappe-bench/env/lib/python3.10/site-packages/redis/_parsers/hiredis.py", line 86, in read_from_socket
    raise ConnectionError(SERVER_CLOSED_CONNECTION_ERROR)
redis.exceptions.ConnectionError: Connection closed by server.
Traceback (most recent call last):
  File "/home/tiendang/projects/frappe-bench/env/lib/python3.10/site-packages/redis/connection.py", line 264, in connect
    sock = self.retry.call_with_retry(
  File "/home/tiendang/projects/frappe-bench/env/lib/python3.10/site-packages/redis/retry.py", line 46, in call_with_retry
    return do()
  File "/home/tiendang/projects/frappe-bench/env/lib/python3.10/site-packages/redis/connection.py", line 265, in <lambda>
    lambda: self._connect(), lambda error: self.disconnect(error)
  File "/home/tiendang/projects/frappe-bench/env/lib/python3.10/site-packages/redis/connection.py", line 627, in _connect
    raise err
  File "/home/tiendang/projects/frappe-bench/env/lib/python3.10/site-packages/redis/connection.py", line 615, in _connect
    sock.connect(socket_address)
ConnectionRefusedError: [Errno 111] Connection refused

During handling of the above exception, another exception occurred:

Traceback (most recent call last):
  File "/usr/lib/python3.10/runpy.py", line 196, in _run_module_as_main
    return _run_code(code, main_globals, None,
  File "/usr/lib/python3.10/runpy.py", line 86, in _run_code
    exec(code, run_globals)
  File "/home/tiendang/projects/frappe-bench/apps/frappe/frappe/utils/bench_helper.py", line 114, in <module>
    main()
  File "/home/tiendang/projects/frappe-bench/apps/frappe/frappe/utils/bench_helper.py", line 20, in main
    click.Group(commands=commands)(prog_name="bench")
  File "/home/tiendang/projects/frappe-bench/env/lib/python3.10/site-packages/click/core.py", line 1157, in __call__
    return self.main(*args, **kwargs)
  File "/home/tiendang/projects/frappe-bench/env/lib/python3.10/site-packages/click/core.py", line 1078, in main
    rv = self.invoke(ctx)
  File "/home/tiendang/projects/frappe-bench/env/lib/python3.10/site-packages/click/core.py", line 1688, in invoke
    return _process_result(sub_ctx.command.invoke(sub_ctx))
  File "/home/tiendang/projects/frappe-bench/env/lib/python3.10/site-packages/click/core.py", line 1688, in invoke
    return _process_result(sub_ctx.command.invoke(sub_ctx))
  File "/home/tiendang/projects/frappe-bench/env/lib/python3.10/site-packages/click/core.py", line 1434, in invoke
    return ctx.invoke(self.callback, **ctx.params)
  File "/home/tiendang/projects/frappe-bench/env/lib/python3.10/site-packages/click/core.py", line 783, in invoke
    return __callback(*args, **kwargs)
  File "/home/tiendang/projects/frappe-bench/apps/frappe/frappe/commands/scheduler.py", line 208, in start_worker
    start_worker(
  File "/home/tiendang/projects/frappe-bench/apps/frappe/frappe/utils/background_jobs.py", line 339, in start_worker
    worker.work(
  File "/home/tiendang/projects/frappe-bench/env/lib/python3.10/site-packages/rq/worker.py", line 456, in work
    self.teardown()
  File "/home/tiendang/projects/frappe-bench/env/lib/python3.10/site-packages/rq/worker.py", line 1047, in teardown
    self.unsubscribe()
  File "/home/tiendang/projects/frappe-bench/env/lib/python3.10/site-packages/rq/worker.py", line 624, in unsubscribe
    self.pubsub.unsubscribe()
  File "/home/tiendang/projects/frappe-bench/env/lib/python3.10/site-packages/redis/client.py", line 941, in unsubscribe
    return self.execute_command("UNSUBSCRIBE", *args)
  File "/home/tiendang/projects/frappe-bench/env/lib/python3.10/site-packages/redis/client.py", line 761, in execute_command
    self._execute(connection, connection.send_command, *args, **kwargs)
  File "/home/tiendang/projects/frappe-bench/env/lib/python3.10/site-packages/redis/client.py", line 800, in _execute
    return conn.retry.call_with_retry(
  File "/home/tiendang/projects/frappe-bench/env/lib/python3.10/site-packages/redis/retry.py", line 49, in call_with_retry
    fail(error)
  File "/home/tiendang/projects/frappe-bench/env/lib/python3.10/site-packages/redis/client.py", line 802, in <lambda>
    lambda error: self._disconnect_raise_connect(conn, error),
  File "/home/tiendang/projects/frappe-bench/env/lib/python3.10/site-packages/redis/client.py", line 789, in _disconnect_raise_connect
    raise error
  File "/home/tiendang/projects/frappe-bench/env/lib/python3.10/site-packages/redis/retry.py", line 46, in call_with_retry
    return do()
  File "/home/tiendang/projects/frappe-bench/env/lib/python3.10/site-packages/redis/client.py", line 801, in <lambda>
    lambda: command(*args, **kwargs),
  File "/home/tiendang/projects/frappe-bench/env/lib/python3.10/site-packages/redis/connection.py", line 464, in send_command
    self.send_packed_command(
  File "/home/tiendang/projects/frappe-bench/env/lib/python3.10/site-packages/redis/connection.py", line 434, in send_packed_command
    self.connect()
  File "/home/tiendang/projects/frappe-bench/env/lib/python3.10/site-packages/redis/connection.py", line 270, in connect
    raise ConnectionError(self._error_message(e))
redis.exceptions.ConnectionError: Error 111 connecting to 127.0.0.1:11000. Connection refused.
Exception in thread Thread-1:
Traceback (most recent call last):
  File "/usr/lib/python3.10/threading.py", line 1016, in _bootstrap_inner
    self.run()
  File "/home/tiendang/projects/frappe-bench/env/lib/python3.10/site-packages/redis/client.py", line 1151, in run
    pubsub.get_message(ignore_subscribe_messages=True, timeout=sleep_time)
  File "/home/tiendang/projects/frappe-bench/env/lib/python3.10/site-packages/redis/client.py", line 1013, in get_message
    response = self.parse_response(block=(timeout is None), timeout=timeout)
  File "/home/tiendang/projects/frappe-bench/env/lib/python3.10/site-packages/redis/client.py", line 824, in parse_response
    response = self._execute(conn, try_read)
  File "/home/tiendang/projects/frappe-bench/env/lib/python3.10/site-packages/redis/client.py", line 800, in _execute
    return conn.retry.call_with_retry(
  File "/home/tiendang/projects/frappe-bench/env/lib/python3.10/site-packages/redis/retry.py", line 49, in call_with_retry
    fail(error)
  File "/home/tiendang/projects/frappe-bench/env/lib/python3.10/site-packages/redis/client.py", line 802, in <lambda>
    lambda error: self._disconnect_raise_connect(conn, error),
  File "/home/tiendang/projects/frappe-bench/env/lib/python3.10/site-packages/redis/client.py", line 789, in _disconnect_raise_connect
    raise error
  File "/home/tiendang/projects/frappe-bench/env/lib/python3.10/site-packages/redis/retry.py", line 46, in call_with_retry
    return do()
  File "/home/tiendang/projects/frappe-bench/env/lib/python3.10/site-packages/redis/client.py", line 801, in <lambda>
    lambda: command(*args, **kwargs),
  File "/home/tiendang/projects/frappe-bench/env/lib/python3.10/site-packages/redis/client.py", line 818, in try_read
    if not conn.can_read(timeout=timeout):
  File "/home/tiendang/projects/frappe-bench/env/lib/python3.10/site-packages/redis/connection.py", line 478, in can_read
    return self._parser.can_read(timeout)
  File "/home/tiendang/projects/frappe-bench/env/lib/python3.10/site-packages/redis/_parsers/hiredis.py", line 75, in can_read
    return self.read_from_socket(timeout=timeout, raise_on_timeout=False)
  File "/home/tiendang/projects/frappe-bench/env/lib/python3.10/site-packages/redis/_parsers/hiredis.py", line 86, in read_from_socket
    raise ConnectionError(SERVER_CLOSED_CONNECTION_ERROR)
redis.exceptions.ConnectionError: Connection closed by server.
Traceback (most recent call last):
  File "/home/tiendang/projects/frappe-bench/env/lib/python3.10/site-packages/redis/connection.py", line 264, in connect
    sock = self.retry.call_with_retry(
  File "/home/tiendang/projects/frappe-bench/env/lib/python3.10/site-packages/redis/retry.py", line 46, in call_with_retry
    return do()
  File "/home/tiendang/projects/frappe-bench/env/lib/python3.10/site-packages/redis/connection.py", line 265, in <lambda>
    lambda: self._connect(), lambda error: self.disconnect(error)
  File "/home/tiendang/projects/frappe-bench/env/lib/python3.10/site-packages/redis/connection.py", line 627, in _connect
    raise err
  File "/home/tiendang/projects/frappe-bench/env/lib/python3.10/site-packages/redis/connection.py", line 615, in _connect
    sock.connect(socket_address)
ConnectionRefusedError: [Errno 111] Connection refused

During handling of the above exception, another exception occurred:

Traceback (most recent call last):
  File "/usr/lib/python3.10/runpy.py", line 196, in _run_module_as_main
    return _run_code(code, main_globals, None,
  File "/usr/lib/python3.10/runpy.py", line 86, in _run_code
    exec(code, run_globals)
  File "/home/tiendang/projects/frappe-bench/apps/frappe/frappe/utils/bench_helper.py", line 114, in <module>
    main()
  File "/home/tiendang/projects/frappe-bench/apps/frappe/frappe/utils/bench_helper.py", line 20, in main
    click.Group(commands=commands)(prog_name="bench")
  File "/home/tiendang/projects/frappe-bench/env/lib/python3.10/site-packages/click/core.py", line 1157, in __call__
    return self.main(*args, **kwargs)
  File "/home/tiendang/projects/frappe-bench/env/lib/python3.10/site-packages/click/core.py", line 1078, in main
    rv = self.invoke(ctx)
  File "/home/tiendang/projects/frappe-bench/env/lib/python3.10/site-packages/click/core.py", line 1688, in invoke
    return _process_result(sub_ctx.command.invoke(sub_ctx))
  File "/home/tiendang/projects/frappe-bench/env/lib/python3.10/site-packages/click/core.py", line 1688, in invoke
    return _process_result(sub_ctx.command.invoke(sub_ctx))
  File "/home/tiendang/projects/frappe-bench/env/lib/python3.10/site-packages/click/core.py", line 1434, in invoke
    return ctx.invoke(self.callback, **ctx.params)
  File "/home/tiendang/projects/frappe-bench/env/lib/python3.10/site-packages/click/core.py", line 783, in invoke
    return __callback(*args, **kwargs)
  File "/home/tiendang/projects/frappe-bench/apps/frappe/frappe/commands/scheduler.py", line 208, in start_worker
    start_worker(
  File "/home/tiendang/projects/frappe-bench/apps/frappe/frappe/utils/background_jobs.py", line 339, in start_worker
    worker.work(
  File "/home/tiendang/projects/frappe-bench/env/lib/python3.10/site-packages/rq/worker.py", line 456, in work
    self.teardown()
  File "/home/tiendang/projects/frappe-bench/env/lib/python3.10/site-packages/rq/worker.py", line 1047, in teardown
    self.unsubscribe()
  File "/home/tiendang/projects/frappe-bench/env/lib/python3.10/site-packages/rq/worker.py", line 624, in unsubscribe
    self.pubsub.unsubscribe()
  File "/home/tiendang/projects/frappe-bench/env/lib/python3.10/site-packages/redis/client.py", line 941, in unsubscribe
    return self.execute_command("UNSUBSCRIBE", *args)
  File "/home/tiendang/projects/frappe-bench/env/lib/python3.10/site-packages/redis/client.py", line 761, in execute_command
    self._execute(connection, connection.send_command, *args, **kwargs)
  File "/home/tiendang/projects/frappe-bench/env/lib/python3.10/site-packages/redis/client.py", line 800, in _execute
    return conn.retry.call_with_retry(
  File "/home/tiendang/projects/frappe-bench/env/lib/python3.10/site-packages/redis/retry.py", line 49, in call_with_retry
    fail(error)
  File "/home/tiendang/projects/frappe-bench/env/lib/python3.10/site-packages/redis/client.py", line 802, in <lambda>
    lambda error: self._disconnect_raise_connect(conn, error),
  File "/home/tiendang/projects/frappe-bench/env/lib/python3.10/site-packages/redis/client.py", line 789, in _disconnect_raise_connect
    raise error
  File "/home/tiendang/projects/frappe-bench/env/lib/python3.10/site-packages/redis/retry.py", line 46, in call_with_retry
    return do()
  File "/home/tiendang/projects/frappe-bench/env/lib/python3.10/site-packages/redis/client.py", line 801, in <lambda>
    lambda: command(*args, **kwargs),
  File "/home/tiendang/projects/frappe-bench/env/lib/python3.10/site-packages/redis/connection.py", line 464, in send_command
    self.send_packed_command(
  File "/home/tiendang/projects/frappe-bench/env/lib/python3.10/site-packages/redis/connection.py", line 434, in send_packed_command
    self.connect()
  File "/home/tiendang/projects/frappe-bench/env/lib/python3.10/site-packages/redis/connection.py", line 270, in connect
    raise ConnectionError(self._error_message(e))
redis.exceptions.ConnectionError: Error 111 connecting to 127.0.0.1:11000. Connection refused.
Exception in thread Thread-1:
Traceback (most recent call last):
  File "/usr/lib/python3.10/threading.py", line 1016, in _bootstrap_inner
    self.run()
  File "/home/tiendang/projects/frappe-bench/env/lib/python3.10/site-packages/redis/client.py", line 1151, in run
    pubsub.get_message(ignore_subscribe_messages=True, timeout=sleep_time)
  File "/home/tiendang/projects/frappe-bench/env/lib/python3.10/site-packages/redis/client.py", line 1013, in get_message
    response = self.parse_response(block=(timeout is None), timeout=timeout)
  File "/home/tiendang/projects/frappe-bench/env/lib/python3.10/site-packages/redis/client.py", line 824, in parse_response
    response = self._execute(conn, try_read)
  File "/home/tiendang/projects/frappe-bench/env/lib/python3.10/site-packages/redis/client.py", line 800, in _execute
    return conn.retry.call_with_retry(
  File "/home/tiendang/projects/frappe-bench/env/lib/python3.10/site-packages/redis/retry.py", line 49, in call_with_retry
    fail(error)
  File "/home/tiendang/projects/frappe-bench/env/lib/python3.10/site-packages/redis/client.py", line 802, in <lambda>
    lambda error: self._disconnect_raise_connect(conn, error),
  File "/home/tiendang/projects/frappe-bench/env/lib/python3.10/site-packages/redis/client.py", line 789, in _disconnect_raise_connect
    raise error
  File "/home/tiendang/projects/frappe-bench/env/lib/python3.10/site-packages/redis/retry.py", line 46, in call_with_retry
    return do()
  File "/home/tiendang/projects/frappe-bench/env/lib/python3.10/site-packages/redis/client.py", line 801, in <lambda>
    lambda: command(*args, **kwargs),
  File "/home/tiendang/projects/frappe-bench/env/lib/python3.10/site-packages/redis/client.py", line 818, in try_read
    if not conn.can_read(timeout=timeout):
  File "/home/tiendang/projects/frappe-bench/env/lib/python3.10/site-packages/redis/connection.py", line 478, in can_read
    return self._parser.can_read(timeout)
  File "/home/tiendang/projects/frappe-bench/env/lib/python3.10/site-packages/redis/_parsers/hiredis.py", line 75, in can_read
    return self.read_from_socket(timeout=timeout, raise_on_timeout=False)
  File "/home/tiendang/projects/frappe-bench/env/lib/python3.10/site-packages/redis/_parsers/hiredis.py", line 86, in read_from_socket
    raise ConnectionError(SERVER_CLOSED_CONNECTION_ERROR)
redis.exceptions.ConnectionError: Connection closed by server.
Traceback (most recent call last):
  File "/home/tiendang/projects/frappe-bench/env/lib/python3.10/site-packages/redis/connection.py", line 264, in connect
    sock = self.retry.call_with_retry(
  File "/home/tiendang/projects/frappe-bench/env/lib/python3.10/site-packages/redis/retry.py", line 46, in call_with_retry
    return do()
  File "/home/tiendang/projects/frappe-bench/env/lib/python3.10/site-packages/redis/connection.py", line 265, in <lambda>
    lambda: self._connect(), lambda error: self.disconnect(error)
  File "/home/tiendang/projects/frappe-bench/env/lib/python3.10/site-packages/redis/connection.py", line 627, in _connect
    raise err
  File "/home/tiendang/projects/frappe-bench/env/lib/python3.10/site-packages/redis/connection.py", line 615, in _connect
    sock.connect(socket_address)
ConnectionRefusedError: [Errno 111] Connection refused

During handling of the above exception, another exception occurred:

Traceback (most recent call last):
  File "/usr/lib/python3.10/runpy.py", line 196, in _run_module_as_main
    return _run_code(code, main_globals, None,
  File "/usr/lib/python3.10/runpy.py", line 86, in _run_code
    exec(code, run_globals)
  File "/home/tiendang/projects/frappe-bench/apps/frappe/frappe/utils/bench_helper.py", line 114, in <module>
    main()
  File "/home/tiendang/projects/frappe-bench/apps/frappe/frappe/utils/bench_helper.py", line 20, in main
    click.Group(commands=commands)(prog_name="bench")
  File "/home/tiendang/projects/frappe-bench/env/lib/python3.10/site-packages/click/core.py", line 1157, in __call__
    return self.main(*args, **kwargs)
  File "/home/tiendang/projects/frappe-bench/env/lib/python3.10/site-packages/click/core.py", line 1078, in main
    rv = self.invoke(ctx)
  File "/home/tiendang/projects/frappe-bench/env/lib/python3.10/site-packages/click/core.py", line 1688, in invoke
    return _process_result(sub_ctx.command.invoke(sub_ctx))
  File "/home/tiendang/projects/frappe-bench/env/lib/python3.10/site-packages/click/core.py", line 1688, in invoke
    return _process_result(sub_ctx.command.invoke(sub_ctx))
  File "/home/tiendang/projects/frappe-bench/env/lib/python3.10/site-packages/click/core.py", line 1434, in invoke
    return ctx.invoke(self.callback, **ctx.params)
  File "/home/tiendang/projects/frappe-bench/env/lib/python3.10/site-packages/click/core.py", line 783, in invoke
    return __callback(*args, **kwargs)
  File "/home/tiendang/projects/frappe-bench/apps/frappe/frappe/commands/scheduler.py", line 208, in start_worker
    start_worker(
  File "/home/tiendang/projects/frappe-bench/apps/frappe/frappe/utils/background_jobs.py", line 339, in start_worker
    worker.work(
  File "/home/tiendang/projects/frappe-bench/env/lib/python3.10/site-packages/rq/worker.py", line 456, in work
    self.teardown()
  File "/home/tiendang/projects/frappe-bench/env/lib/python3.10/site-packages/rq/worker.py", line 1047, in teardown
    self.unsubscribe()
  File "/home/tiendang/projects/frappe-bench/env/lib/python3.10/site-packages/rq/worker.py", line 624, in unsubscribe
    self.pubsub.unsubscribe()
  File "/home/tiendang/projects/frappe-bench/env/lib/python3.10/site-packages/redis/client.py", line 941, in unsubscribe
    return self.execute_command("UNSUBSCRIBE", *args)
  File "/home/tiendang/projects/frappe-bench/env/lib/python3.10/site-packages/redis/client.py", line 761, in execute_command
    self._execute(connection, connection.send_command, *args, **kwargs)
  File "/home/tiendang/projects/frappe-bench/env/lib/python3.10/site-packages/redis/client.py", line 800, in _execute
    return conn.retry.call_with_retry(
  File "/home/tiendang/projects/frappe-bench/env/lib/python3.10/site-packages/redis/retry.py", line 49, in call_with_retry
    fail(error)
  File "/home/tiendang/projects/frappe-bench/env/lib/python3.10/site-packages/redis/client.py", line 802, in <lambda>
    lambda error: self._disconnect_raise_connect(conn, error),
  File "/home/tiendang/projects/frappe-bench/env/lib/python3.10/site-packages/redis/client.py", line 789, in _disconnect_raise_connect
    raise error
  File "/home/tiendang/projects/frappe-bench/env/lib/python3.10/site-packages/redis/retry.py", line 46, in call_with_retry
    return do()
  File "/home/tiendang/projects/frappe-bench/env/lib/python3.10/site-packages/redis/client.py", line 801, in <lambda>
    lambda: command(*args, **kwargs),
  File "/home/tiendang/projects/frappe-bench/env/lib/python3.10/site-packages/redis/connection.py", line 464, in send_command
    self.send_packed_command(
  File "/home/tiendang/projects/frappe-bench/env/lib/python3.10/site-packages/redis/connection.py", line 434, in send_packed_command
    self.connect()
  File "/home/tiendang/projects/frappe-bench/env/lib/python3.10/site-packages/redis/connection.py", line 270, in connect
    raise ConnectionError(self._error_message(e))
redis.exceptions.ConnectionError: Error 111 connecting to 127.0.0.1:11000. Connection refused.
